Workbook

Sheet Instructions
A1: Fire Prevention in HEIs – Monitoring Workbook
A2: Companion to the Fire Prevention SOP
A4: How to use
A5: Yellow cells, blue text | B5: Input cells – type or pick from the drop-down. Only edit these.
A6: Grey cells | B6: Auto-calculated formulas – do not overwrite.
A7: Green / amber / red | B7: Status highlighting is applied automatically. Dark red = critical / escalate.
A8: Sample data | B8: Registers hold example rows from a campus scenario so the Dashboard shows results. Overwrite or clear before use.
A9: Report date | B9: Dashboard C5 defaults to TODAY(). Overwrite with a fixed date to report as of that date.
A10: Parameters | B10: Risk thresholds and warning windows are on the Lists sheet (column R).
A11: Sheets
A12: Dashboard | B12: SOP Section 17 KPIs plus supporting indicators, items needing attention and hazards by category.
A13: Fire Risk Register | B13: SOP Section 5: hazard, likelihood × consequence, risk level, controls, action owner and date, residual risk.
A14: Inspection Checklist | B14: SOP Section 13: 15 inspection items; critical life-safety deficiencies flagged for escalation.
A15: Inspection Schedule | B15: Planned vs completed inspections and critical deficiencies found – drives KPIs 17.1 and 17.5.
A16: Hazard Reports & CAPA | B16: SOP Section 15: record, assess, protect, assign, deadline, verify, update register, escalate.
A17: Fire Protection Register | B17: SOP Section 12: equipment service dates, impairments and interim controls – drives KPI 17.4.
A18: Hot-Work Permits | B18: SOP Section 11: the 10 permit conditions; work must STOP if any essential condition is not met.
A19: Flammable Inventory | B19: SOP Section 8: quantities vs permitted limits, approved storage, segregation, labelling, cylinders.
A20: Hostel & Kitchen Checks | B20: SOP Sections 9 and 10: residential and kitchen fire-prevention controls.
A21: Training Records | B21: SOP Section 14: training by role and module, expiry – drives KPI 17.3.
A22: Fire Drill Register | B22: Fire drill reports (Section 18 records).
A23: RACI Matrix | B23: SOP Section 16 with an automatic check that each activity has one Accountable role.
A24: Lists | B24: Drop-down sources and adjustable parameters.

Sheet Dashboard
A1: Fire Prevention – KPI Dashboard
A2: SOP Section 17 – Fire Prevention KPIs (auto-calculated from the registers)
B4: Institution / campus | C4: Main Campus
B5: Report date | C5: =TODAY() -> 46305
A7: # | B7: KPI | C7: Formula | D7: Actual | E7: Target | F7: Direction | G7: Status | H7: Source
A8: 17.1 | B8: Fire safety inspection compliance | C8: Inspections completed ÷ inspections planned (due to date) × 100 | D8: =IFERROR(COUNTIF('Inspection Schedule'!K5:K154,"Completed")/(COUNTIF('Inspection Schedule'!K5:K154,"Completed")+COUNTIF('Inspection Schedule'!K5:K154,"Missed")),"") -> 0.75 | E8: 0.95 | F8: Higher is better | G8: =IF(D8="","No data",IF(D8>=E8,"On target",IF(D8>=E8*0.9,"Watch","Action needed"))) -> Action needed | H8: Inspection Schedule
A9: 17.2 | B9: Fire hazard closure rate | C9: Hazards closed (verified) ÷ hazards reported × 100 | D9: =IFERROR(COUNTIF('Hazard Reports & CAPA'!P5:P64,"Closed")/COUNT('Hazard Reports & CAPA'!B5:B64),"") -> 0.2 | E9: 0.9 | F9: Higher is better | G9: =IF(D9="","No data",IF(D9>=E9,"On target",IF(D9>=E9*0.9,"Watch","Action needed"))) -> Action needed | H9: Hazard Reports & CAPA
A10: 17.3 | B10: Fire safety training compliance | C10: Personnel with current training ÷ personnel requiring training × 100 | D10: =IFERROR(COUNTIF('Training Records'!I5:I204,"Current")/COUNTIF('Training Records'!D5:D204,"Yes"),"") -> 0.4 | E10: 0.95 | F10: Higher is better | G10: =IF(D10="","No data",IF(D10>=E10,"On target",IF(D10>=E10*0.9,"Watch","Action needed"))) -> Action needed | H10: Training Records
A11: 17.4 | B11: Fire protection maintenance compliance | C11: Equipment within service schedule ÷ equipment requiring service × 100 | D11: =IFERROR((COUNTIF('Fire Protection Register'!J5:J154,"In service")+COUNTIF('Fire Protection Register'!J5:J154,"Due soon"))/COUNTA('Fire Protection Register'!B5:B154),"") -> 0.625 | E11: 1 | F11: Higher is better | G11: =IF(D11="","No data",IF(D11>=E11,"On target",IF(D11>=E11*0.9,"Watch","Action needed"))) -> Action needed | H11: Fire Protection Register
A12: 17.5 | B12: Critical fire safety deficiency rate | C12: Critical deficiencies found ÷ inspections conducted (rate per inspection) | D12: =IFERROR(SUM('Inspection Schedule'!J5:J154)/COUNTIF('Inspection Schedule'!K5:K154,"Completed"),"") -> 0.33333333 | E12: 0 | F12: Lower is better | G12: =IF(D12="","No data",IF(D12<=E12,"On target","Action needed")) -> Action needed | H12: Inspection Schedule
A13: S1 | B13: High / critical residual fire risks | C13: Fire Risk Register – residual level High or Critical | D13: =COUNTIF('Fire Risk Register'!R5:R64,"High")+COUNTIF('Fire Risk Register'!R5:R64,"Critical") -> 0 | E13: 0 | F13: Lower is better | G13: =IF(D13="","No data",IF(D13<=E13,"On target","Action needed")) -> On target | H13: Fire Risk Register
A14: S2 | B14: Flammable storage compliance | C14: Compliant items ÷ inventory items × 100 | D14: =IFERROR(COUNTIF('Flammable Inventory'!M5:M104,"Compliant")/COUNTA('Flammable Inventory'!B5:B104),"") -> 0.6 | E14: 1 | F14: Higher is better | G14: =IF(D14="","No data",IF(D14>=E14,"On target",IF(D14>=E14*0.9,"Watch","Action needed"))) -> Action needed | H14: Flammable Inventory
A15: S3 | B15: Hot-work permit compliance | C15: Permits with all conditions met ÷ permits issued × 100 | D15: =IFERROR(COUNTIF('Hot-Work Permits'!P5:P64,"All conditions met")/COUNTA('Hot-Work Permits'!C5:C64),"") -> 0.66666667 | E15: 1 | F15: Higher is better | G15: =IF(D15="","No data",IF(D15>=E15,"On target",IF(D15>=E15*0.9,"Watch","Action needed"))) -> Action needed | H15: Hot-Work Permits
A16: S4 | B16: Fire drill completion | C16: Drills completed ÷ drills planned (due to date) × 100 | D16: =IFERROR(COUNTIF('Fire Drill Register'!J5:J34,"Completed")/(COUNTIF('Fire Drill Register'!J5:J34,"Completed")+COUNTIF('Fire Drill Register'!J5:J34,"Missed")),"") -> 0.5 | E16: 1 | F16: Higher is better | G16: =IF(D16="","No data",IF(D16>=E16,"On target",IF(D16>=E16*0.9,"Watch","Action needed"))) -> Action needed | H16: Fire Drill Register
B17: 17.1–17.5 are the SOP KPIs; S1–S4 are supporting indicators. Targets (yellow) are suggested – set them to your institution's approved values.
B19: Items needing attention | C19: Source | D19: Count
B20: Hazards to ESCALATE (critical open or overdue) | C20: Hazard Reports & CAPA | D20: =COUNTIF('Hazard Reports & CAPA'!Q5:Q64,"ESCALATE") -> 2
B21: Hazards awaiting effectiveness verification | C21: Hazard Reports & CAPA | D21: =COUNTIF('Hazard Reports & CAPA'!P5:P64,"Awaiting verification") -> 1
B22: Critical deficiencies – latest checklist | C22: Inspection Checklist | D22: ='Inspection Checklist'!$D$30 -> 1
B23: Non-compliant items – latest checklist | C23: Inspection Checklist | D23: ='Inspection Checklist'!$D$26 -> 2
B24: Fire risk actions overdue | C24: Fire Risk Register | D24: =COUNTIF('Fire Risk Register'!S5:S64,"Overdue") -> 1
B25: Critical systems impaired with NO interim control | C25: Fire Protection Register | D25: =COUNTIF('Fire Protection Register'!J5:J154,"IMPAIRED – NO INTERIM CONTROL") -> 0
B26: Fire protection equipment impaired / service overdue | C26: Fire Protection Register | D26: =COUNTIF('Fire Protection Register'!J5:J154,"Service overdue")+COUNTIF('Fire Protection Register'!J5:J154,"Impaired*") -> 3
B27: Hot-work permits – STOP | C27: Hot-Work Permits | D27: =COUNTIF('Hot-Work Permits'!Q5:Q64,"STOP – do not permit") -> 1
B28: Flammable items needing action | C28: Flammable Inventory | D28: =COUNTIF('Flammable Inventory'!M5:M104,"Action needed") -> 2
B29: Hostel non-compliances | C29: Hostel & Kitchen Checks | D29: ='Hostel & Kitchen Checks'!C19 -> 2
B30: Kitchen non-compliances | C30: Hostel & Kitchen Checks | D30: ='Hostel & Kitchen Checks'!C35 -> 0
B31: Inspections missed | C31: Inspection Schedule | D31: =COUNTIF('Inspection Schedule'!K5:K154,"Missed") -> 1
B32: Training expired / expiring / not trained | C32: Training Records | D32: =COUNTIF('Training Records'!I5:I204,"Expired")+COUNTIF('Training Records'!I5:I204,"Expiring")+COUNTIF('Training Records'!I5:I204,"Not trained") -> 3
B33: Fire drills missed | C33: Fire Drill Register | D33: =COUNTIF('Fire Drill Register'!J5:J34,"Missed") -> 1
B36: Hazard category | C36: Hazards reported
B37: Electrical | C37: =COUNTIF('Hazard Reports & CAPA'!E5:E64,B37) -> 0
B38: Laboratory | C38: =COUNTIF('Hazard Reports & CAPA'!E5:E64,B38) -> 0
B39: Kitchen | C39: =COUNTIF('Hazard Reports & CAPA'!E5:E64,B39) -> 1
B40: Storage | C40: =COUNTIF('Hazard Reports & CAPA'!E5:E64,B40) -> 1
B41: Hot Work | C41: =COUNTIF('Hazard Reports & CAPA'!E5:E64,B41) -> 0
B42: Smoking/Open Flames | C42: =COUNTIF('Hazard Reports & CAPA'!E5:E64,B42) -> 0
B43: Battery/Charging | C43: =COUNTIF('Hazard Reports & CAPA'!E5:E64,B43) -> 1
B44: Construction | C44: =COUNTIF('Hazard Reports & CAPA'!E5:E64,B44) -> 0
B45: Waste Management | C45: =COUNTIF('Hazard Reports & CAPA'!E5:E64,B45) -> 1
...

Sheet Fire Risk Register
A1: Fire Risk Assessment Register
A2: SOP Section 5 – hazards, risk ratings, existing controls, required actions, owners and completion dates
A4: Ref | B4: Area / location | C4: Premises type | D4: Hazard category | E4: Hazard description | F4: Likelihood (1-5) | G4: Consequence (1-5) | H4: Risk score | I4: Risk level | J4: Existing controls | K4: Required action | L4: Owner | M4: Target date | N4: Completed date | O4: Residual likelihood | P4: Residual consequence | Q4: Residual score | R4: Residual level | S4: Action status
A5: =IF(B5="","","FR-"&TEXT(ROW()-4,"000")) -> FR-001 | B5: Chemistry Lab 2 | C5: Laboratory / research centre | D5: Laboratory | E5: Flammable solvents near hot plates | F5: 3 | G5: 4 | H5: =IF(OR(F5="",G5=""),"",F5*G5) -> 12 | I5: =IF(H5="","",IF(H5<=Lists!$R$2,"Low",IF(H5<=Lists!$R$3,"Medium",IF(H5<=Lists!$R$4,"High","Critical")))) -> High | J5: Flammables cabinet; supervised use | K5: Relocate hot plates; set bench quantity limits | L5: Laboratory In-charge | M5: 46315 | O5: 2 | P5: 3 | Q5: =IF(OR(O5="",P5=""),"",O5*P5) -> 6 | R5: =IF(Q5="","",IF(Q5<=Lists!$R$2,"Low",IF(Q5<=Lists!$R$3,"Medium",IF(Q5<=Lists!$R$4,"High","Critical")))) -> Medium | S5: =IF(B5="","",IF(K5="","No action required",IF(N5<>"","Complete",IF(M5="","No target date",IF(M5<Dashboard!$C$5,"Overdue",IF(M5-Dashboard!$C$5<=Lists!$R$5,"Due soon","Open")))))) -> Due soon
A6: =IF(B6="","","FR-"&TEXT(ROW()-4,"000")) -> FR-002 | B6: Boys Hostel B – rooms | C6: Hostel / residential | D6: Battery/Charging | E6: Unapproved chargers and high-load heaters in rooms | F6: 4 | G6: 4 | H6: =IF(OR(F6="",G6=""),"",F6*G6) -> 16 | I6: =IF(H6="","",IF(H6<=Lists!$R$2,"Low",IF(H6<=Lists!$R$3,"Medium",IF(H6<=Lists!$R$4,"High","Critical")))) -> Critical | J6: Hostel rules; monthly warden rounds | K6: Room inspections; confiscate prohibited devices; resident briefing | L6: Hostel Warden | M6: 46300 | O6: 3 | P6: 3 | Q6: =IF(OR(O6="",P6=""),"",O6*P6) -> 9 | R6: =IF(Q6="","",IF(Q6<=Lists!$R$2,"Low",IF(Q6<=Lists!$R$3,"Medium",IF(Q6<=Lists!$R$4,"High","Critical")))) -> Medium | S6: =IF(B6="","",IF(K6="","No action required",IF(N6<>"","Complete",IF(M6="","No target date",IF(M6<Dashboard!$C$5,"Overdue",IF(M6-Dashboard!$C$5<=Lists!$R$5,"Due soon","Open")))))) -> Overdue
A7: =IF(B7="","","FR-"&TEXT(ROW()-4,"000")) -> FR-003 | B7: Central kitchen | C7: Kitchen / cafeteria | D7: Kitchen | E7: Grease accumulation in hood and duct | F7: 3 | G7: 5 | H7: =IF(OR(F7="",G7=""),"",F7*G7) -> 15 | I7: =IF(H7="","",IF(H7<=Lists!$R$2,"Low",IF(H7<=Lists!$R$3,"Medium",IF(H7<=Lists!$R$4,"High","Critical")))) -> Critical | J7: Weekly hood cleaning | K7: Quarterly duct cleaning by contractor | L7: Canteen/Kitchen Supervisor | M7: 46295 | N7: 46293 | O7: 2 | P7: 4 | Q7: =IF(OR(O7="",P7=""),"",O7*P7) -> 8 | R7: =IF(Q7="","",IF(Q7<=Lists!$R$2,"Low",IF(Q7<=Lists!$R$3,"Medium",IF(Q7<=Lists!$R$4,"High","Critical")))) -> Medium | S7: =IF(B7="","",IF(K7="","No action required",IF(N7<>"","Complete",IF(M7="","No target date",IF(M7<Dashboard!$C$5,"Overdue",IF(M7-Dashboard!$C$5<=Lists!$R$5,"Due soon","Open")))))) -> Complete
A8: =IF(B8="","","FR-"&TEXT(ROW()-4,"000")) -> FR-004 | B8: Main electrical room | C8: Electrical room / server room / data centre | D8: Electrical | E8: Combustible storage near LT panel | F8: 3 | G8: 5 | H8: =IF(OR(F8="",G8=""),"",F8*G8) -> 15 | I8: =IF(H8="","",IF(H8<=Lists!$R$2,"Low",IF(H8<=Lists!$R$3,"Medium",IF(H8<=Lists!$R$4,"High","Critical")))) -> Critical | J8: Restricted access | K8: Clear storage; mark keep-clear zone | L8: Infrastructure/Maintenance Officer | M8: 46310 | O8: 1 | P8: 4 | Q8: =IF(OR(O8="",P8=""),"",O8*P8) -> 4 | R8: =IF(Q8="","",IF(Q8<=Lists!$R$2,"Low",IF(Q8<=Lists!$R$3,"Medium",IF(Q8<=Lists!$R$4,"High","Critical")))) -> Low | S8: =IF(B8="","",IF(K8="","No action required",IF(N8<>"","Complete",IF(M8="","No target date",IF(M8<Dashboard!$C$5,"Overdue",IF(M8-Dashboard!$C$5<=Lists!$R$5,"Due soon","Open")))))) -> Due soon
A9: =IF(B9="","","FR-"&TEXT(ROW()-4,"000")) -> FR-005 | B9: Library stack area | C9: Library / auditorium / hall | D9: Storage | E9: Packaging and waste paper accumulation | F9: 2 | G9: 3 | H9: =IF(OR(F9="",G9=""),"",F9*G9) -> 6 | I9: =IF(H9="","",IF(H9<=Lists!$R$2,"Low",IF(H9<=Lists!$R$3,"Medium",IF(H9<=Lists!$R$4,"High","Critical")))) -> Medium | J9: Daily housekeeping | L9: Department Head | O9: 2 | P9: 3 | Q9: =IF(OR(O9="",P9=""),"",O9*P9) -> 6 | R9: =IF(Q9="","",IF(Q9<=Lists!$R$2,"Low",IF(Q9<=Lists!$R$3,"Medium",IF(Q9<=Lists!$R$4,"High","Critical")))) -> Medium | S9: =IF(B9="","",IF(K9="","No action required",IF(N9<>"","Complete",IF(M9="","No target date",IF(M9<Dashboard!$C$5,"Overdue",IF(M9-Dashboard!$C$5<=Lists!$R$5,"Due soon","Open")))))) -> No action required
A10: =IF(B10="","","FR-"&TEXT(ROW()-4,"000")) | H10: =IF(OR(F10="",G10=""),"",F10*G10) | I10: =IF(H10="","",IF(H10<=Lists!$R$2,"Low",IF(H10<=Lists!$R$3,"Medium",IF(H10<=Lists!$R$4,"High","Critical")))) | Q10: =IF(OR(O10="",P10=""),"",O10*P10) | R10: =IF(Q10="","",IF(Q10<=Lists!$R$2,"Low",IF(Q10<=Lists!$R$3,"Medium",IF(Q10<=Lists!$R$4,"High","Critical")))) | S10: =IF(B10="","",IF(K10="","No action required",IF(N10<>"","Complete",IF(M10="","No target date",IF(M10<Dashboard!$C$5,"Overdue",IF(M10-Dashboard!$C$5<=Lists!$R$5,"Due soon","Open"))))))
A11: =IF(B11="","","FR-"&TEXT(ROW()-4,"000")) | H11: =IF(OR(F11="",G11=""),"",F11*G11) | I11: =IF(H11="","",IF(H11<=Lists!$R$2,"Low",IF(H11<=Lists!$R$3,"Medium",IF(H11<=Lists!$R$4,"High","Critical")))) | Q11: =IF(OR(O11="",P11=""),"",O11*P11) | R11: =IF(Q11="","",IF(Q11<=Lists!$R$2,"Low",IF(Q11<=Lists!$R$3,"Medium",IF(Q11<=Lists!$R$4,"High","Critical")))) | S11: =IF(B11="","",IF(K11="","No action required",IF(N11<>"","Complete",IF(M11="","No target date",IF(M11<Dashboard!$C$5,"Overdue",IF(M11-Dashboard!$C$5<=Lists!$R$5,"Due soon","Open"))))))
A12: =IF(B12="","","FR-"&TEXT(ROW()-4,"000")) | H12: =IF(OR(F12="",G12=""),"",F12*G12) | I12: =IF(H12="","",IF(H12<=Lists!$R$2,"Low",IF(H12<=Lists!$R$3,"Medium",IF(H12<=Lists!$R$4,"High","Critical")))) | Q12: =IF(OR(O12="",P12=""),"",O12*P12) | R12: =IF(Q12="","",IF(Q12<=Lists!$R$2,"Low",IF(Q12<=Lists!$R$3,"Medium",IF(Q12<=Lists!$R$4,"High","Critical")))) | S12: =IF(B12="","",IF(K12="","No action required",IF(N12<>"","Complete",IF(M12="","No target date",IF(M12<Dashboard!$C$5,"Overdue",IF(M12-Dashboard!$C$5<=Lists!$R$5,"Due soon","Open"))))))
A13: =IF(B13="","","FR-"&TEXT(ROW()-4,"000")) | H13: =IF(OR(F13="",G13=""),"",F13*G13) | I13: =IF(H13="","",IF(H13<=Lists!$R$2,"Low",IF(H13<=Lists!$R$3,"Medium",IF(H13<=Lists!$R$4,"High","Critical")))) | Q13: =IF(OR(O13="",P13=""),"",O13*P13) | R13: =IF(Q13="","",IF(Q13<=Lists!$R$2,"Low",IF(Q13<=Lists!$R$3,"Medium",IF(Q13<=Lists!$R$4,"High","Critical")))) | S13: =IF(B13="","",IF(K13="","No action required",IF(N13<>"","Complete",IF(M13="","No target date",IF(M13<Dashboard!$C$5,"Overdue",IF(M13-Dashboard!$C$5<=Lists!$R$5,"Due soon","Open"))))))
A14: =IF(B14="","","FR-"&TEXT(ROW()-4,"000")) | H14: =IF(OR(F14="",G14=""),"",F14*G14) | I14: =IF(H14="","",IF(H14<=Lists!$R$2,"Low",IF(H14<=Lists!$R$3,"Medium",IF(H14<=Lists!$R$4,"High","Critical")))) | Q14: =IF(OR(O14="",P14=""),"",O14*P14) | R14: =IF(Q14="","",IF(Q14<=Lists!$R$2,"Low",IF(Q14<=Lists!$R$3,"Medium",IF(Q14<=Lists!$R$4,"High","Critical")))) | S14: =IF(B14="","",IF(K14="","No action required",IF(N14<>"","Complete",IF(M14="","No target date",IF(M14<Dashboard!$C$5,"Overdue",IF(M14-Dashboard!$C$5<=Lists!$R$5,"Due soon","Open"))))))
A15: =IF(B15="","","FR-"&TEXT(ROW()-4,"000")) | H15: =IF(OR(F15="",G15=""),"",F15*G15) | I15: =IF(H15="","",IF(H15<=Lists!$R$2,"Low",IF(H15<=Lists!$R$3,"Medium",IF(H15<=Lists!$R$4,"High","Critical")))) | Q15: =IF(OR(O15="",P15=""),"",O15*P15) | R15: =IF(Q15="","",IF(Q15<=Lists!$R$2,"Low",IF(Q15<=Lists!$R$3,"Medium",IF(Q15<=Lists!$R$4,"High","Critical")))) | S15: =IF(B15="","",IF(K15="","No action required",IF(N15<>"","Complete",IF(M15="","No target date",IF(M15<Dashboard!$C$5,"Overdue",IF(M15-Dashboard!$C$5<=Lists!$R$5,"Due soon","Open"))))))
A16: =IF(B16="","","FR-"&TEXT(ROW()-4,"000")) | H16: =IF(OR(F16="",G16=""),"",F16*G16) | I16: =IF(H16="","",IF(H16<=Lists!$R$2,"Low",IF(H16<=Lists!$R$3,"Medium",IF(H16<=Lists!$R$4,"High","Critical")))) | Q16: =IF(OR(O16="",P16=""),"",O16*P16) | R16: =IF(Q16="","",IF(Q16<=Lists!$R$2,"Low",IF(Q16<=Lists!$R$3,"Medium",IF(Q16<=Lists!$R$4,"High","Critical")))) | S16: =IF(B16="","",IF(K16="","No action required",IF(N16<>"","Complete",IF(M16="","No target date",IF(M16<Dashboard!$C$5,"Overdue",IF(M16-Dashboard!$C$5<=Lists!$R$5,"Due soon","Open"))))))
A17: =IF(B17="","","FR-"&TEXT(ROW()-4,"000")) | H17: =IF(OR(F17="",G17=""),"",F17*G17) | I17: =IF(H17="","",IF(H17<=Lists!$R$2,"Low",IF(H17<=Lists!$R$3,"Medium",IF(H17<=Lists!$R$4,"High","Critical")))) | Q17: =IF(OR(O17="",P17=""),"",O17*P17) | R17: =IF(Q17="","",IF(Q17<=Lists!$R$2,"Low",IF(Q17<=Lists!$R$3,"Medium",IF(Q17<=Lists!$R$4,"High","Critical")))) | S17: =IF(B17="","",IF(K17="","No action required",IF(N17<>"","Complete",IF(M17="","No target date",IF(M17<Dashboard!$C$5,"Overdue",IF(M17-Dashboard!$C$5<=Lists!$R$5,"Due soon","Open"))))))
A18: =IF(B18="","","FR-"&TEXT(ROW()-4,"000")) | H18: =IF(OR(F18="",G18=""),"",F18*G18) | I18: =IF(H18="","",IF(H18<=Lists!$R$2,"Low",IF(H18<=Lists!$R$3,"Medium",IF(H18<=Lists!$R$4,"High","Critical")))) | Q18: =IF(OR(O18="",P18=""),"",O18*P18) | R18: =IF(Q18="","",IF(Q18<=Lists!$R$2,"Low",IF(Q18<=Lists!$R$3,"Medium",IF(Q18<=Lists!$R$4,"High","Critical")))) | S18: =IF(B18="","",IF(K18="","No action required",IF(N18<>"","Complete",IF(M18="","No target date",IF(M18<Dashboard!$C$5,"Overdue",IF(M18-Dashboard!$C$5<=Lists!$R$5,"Due soon","Open"))))))
A19: =IF(B19="","","FR-"&TEXT(ROW()-4,"000")) | H19: =IF(OR(F19="",G19=""),"",F19*G19) | I19: =IF(H19="","",IF(H19<=Lists!$R$2,"Low",IF(H19<=Lists!$R$3,"Medium",IF(H19<=Lists!$R$4,"High","Critical")))) | Q19: =IF(OR(O19="",P19=""),"",O19*P19) | R19: =IF(Q19="","",IF(Q19<=Lists!$R$2,"Low",IF(Q19<=Lists!$R$3,"Medium",IF(Q19<=Lists!$R$4,"High","Critical")))) | S19: =IF(B19="","",IF(K19="","No action required",IF(N19<>"","Complete",IF(M19="","No target date",IF(M19<Dashboard!$C$5,"Overdue",IF(M19-Dashboard!$C$5<=Lists!$R$5,"Due soon","Open"))))))
A20: =IF(B20="","","FR-"&TEXT(ROW()-4,"000")) | H20: =IF(OR(F20="",G20=""),"",F20*G20) | I20: =IF(H20="","",IF(H20<=Lists!$R$2,"Low",IF(H20<=Lists!$R$3,"Medium",IF(H20<=Lists!$R$4,"High","Critical")))) | Q20: =IF(OR(O20="",P20=""),"",O20*P20) | R20: =IF(Q20="","",IF(Q20<=Lists!$R$2,"Low",IF(Q20<=Lists!$R$3,"Medium",IF(Q20<=Lists!$R$4,"High","Critical")))) | S20: =IF(B20="","",IF(K20="","No action required",IF(N20<>"","Complete",IF(M20="","No target date",IF(M20<Dashboard!$C$5,"Overdue",IF(M20-Dashboard!$C$5<=Lists!$R$5,"Due soon","Open"))))))
A21: =IF(B21="","","FR-"&TEXT(ROW()-4,"000")) | H21: =IF(OR(F21="",G21=""),"",F21*G21) | I21: =IF(H21="","",IF(H21<=Lists!$R$2,"Low",IF(H21<=Lists!$R$3,"Medium",IF(H21<=Lists!$R$4,"High","Critical")))) | Q21: =IF(OR(O21="",P21=""),"",O21*P21) | R21: =IF(Q21="","",IF(Q21<=Lists!$R$2,"Low",IF(Q21<=Lists!$R$3,"Medium",IF(Q21<=Lists!$R$4,"High","Critical")))) | S21: =IF(B21="","",IF(K21="","No action required",IF(N21<>"","Complete",IF(M21="","No target date",IF(M21<Dashboard!$C$5,"Overdue",IF(M21-Dashboard!$C$5<=Lists!$R$5,"Due soon","Open"))))))
... A64: =IF(B64="","","FR-"&TEXT(ROW()-4,"000")) | H64: =IF(OR(F64="",G64=""),"",F64*G64) | I64: =IF(H64="","",IF(H64<=Lists!$R$2,"Low",IF(H64<=Lists!$R$3,"Medium",IF(H64<=Lists!$R$4,"High","Critical")))) | Q64: =IF(OR(O64="",P64=""),"",O64*P64) | R64: =IF(Q64="","",IF(Q64<=Lists!$R$2,"Low",IF(Q64<=Lists!$R$3,"Medium",IF(Q64<=Lists!$R$4,"High","Critical")))) | S64: =IF(B64="","",IF(K64="","No action required",IF(N64<>"","Complete",IF(M64="","No target date",IF(M64<Dashboard!$C$5,"Overdue",IF(M64-Dashboard!$C$5<=Lists!$R$5,"Due soon","Open"))))))
B66: Scoring guide
B67: Score | C67: Likelihood of ignition / spread | D67: Consequence
B68: 1 | C68: Rare | D68: Negligible – no injury, minor damage
B69: 2 | C69: Unlikely | D69: Minor – first aid, local damage
B70: 3 | C70: Possible | D70: Moderate – injury, room-level damage, disruption
B71: 4 | C71: Likely | D71: Major – serious injury, building damage, evacuation
B72: 5 | C72: Almost certain | D72: Severe – fatality, loss of critical facility
B73: Assessment should consider occupancy, evacuation difficulty, life safety, critical infrastructure and adequacy of existing controls (Section 5).

Sheet Inspection Checklist
A1: Fire Safety Inspection Checklist
A2: SOP Section 13 – any critical deficiency affecting life safety shall be escalated promptly
A4: Building / area | B4: Academic Block A
A5: Inspection date | B5: 46302
A6: Inspected by | B6: Fire and Safety Officer
A8: # | B8: Inspection item | C8: Verification requirement | D8: Status | E8: Life-safety critical? | F8: Escalation | G8: Observation / action required | H8: Owner / target date
A9: 1 | B9: Electrical installations | C9: No visible damage, unsafe connections or unresolved defects | D9: Compliant | F9: =IF(D9="Non-compliant",IF(E9="Yes","ESCALATE NOW","Corrective action"),"—") -> —
A10: 2 | B10: Electrical panels | C10: Accessible, protected and free from combustible storage | D10: Non-compliant | E10: No | F10: =IF(D10="Non-compliant",IF(E10="Yes","ESCALATE NOW","Corrective action"),"—") -> Corrective action | G10: Cartons stored beside DB-3 | H10: Maintenance – 14-Oct
A11: 3 | B11: Laboratories | C11: Chemicals stored safely; equipment and ignition controls maintained | D11: Compliant | F11: =IF(D11="Non-compliant",IF(E11="Yes","ESCALATE NOW","Corrective action"),"—") -> —
A12: 4 | B12: Kitchens | C12: Cooking equipment, ventilation and fuel systems inspected | D12: N/A | F12: =IF(D12="Non-compliant",IF(E12="Yes","ESCALATE NOW","Corrective action"),"—") -> —
A13: 5 | B13: Storage areas | C13: Combustible materials controlled and chemicals appropriately stored | D13: Compliant | F13: =IF(D13="Non-compliant",IF(E13="Yes","ESCALATE NOW","Corrective action"),"—") -> —
A14: 6 | B14: Escape routes | C14: Corridors, staircases and exits unobstructed | D14: Compliant | F14: =IF(D14="Non-compliant",IF(E14="Yes","ESCALATE NOW","Corrective action"),"—") -> —
A15: 7 | B15: Fire doors | C15: Functional and not improperly wedged open | D15: Non-compliant | E15: Yes | F15: =IF(D15="Non-compliant",IF(E15="Yes","ESCALATE NOW","Corrective action"),"—") -> ESCALATE NOW | G15: Fire door to stair 2 wedged open with chair | H15: Security Officer – immediate
A16: 8 | B16: Fire equipment | C16: Accessible, inspected and within service requirements | D16: Compliant | F16: =IF(D16="Non-compliant",IF(E16="Yes","ESCALATE NOW","Corrective action"),"—") -> —
A17: 9 | B17: Detection and alarms | C17: Testing and maintenance records current | D17: Compliant | F17: =IF(D17="Non-compliant",IF(E17="Yes","ESCALATE NOW","Corrective action"),"—") -> —
A18: 10 | B18: Emergency lighting | C18: Operational according to the inspection schedule | D18: Compliant | F18: =IF(D18="Non-compliant",IF(E18="Yes","ESCALATE NOW","Corrective action"),"—") -> —
A19: 11 | B19: Waste | C19: Combustible waste removed appropriately | D19: Compliant | F19: =IF(D19="Non-compliant",IF(E19="Yes","ESCALATE NOW","Corrective action"),"—") -> —
A20: 12 | B20: Hot work | C20: Required permits and controls in place | D20: Compliant | F20: =IF(D20="Non-compliant",IF(E20="Yes","ESCALATE NOW","Corrective action"),"—") -> —
A21: 13 | B21: Contractors | C21: Safety instructions and supervision provided | D21: Compliant | F21: =IF(D21="Non-compliant",IF(E21="Yes","ESCALATE NOW","Corrective action"),"—") -> —
A22: 14 | B22: Training | C22: Required personnel training current | D22: Compliant | F22: =IF(D22="Non-compliant",IF(E22="Yes","ESCALATE NOW","Corrective action"),"—") -> —
A23: 15 | B23: Records | C23: Defects documented and corrective actions tracked | D23: Compliant | F23: =IF(D23="Non-compliant",IF(E23="Yes","ESCALATE NOW","Corrective action"),"—") -> —
B25: Compliant | D25: =COUNTIF(D9:D23,"Compliant") -> 12
B26: Non-compliant | D26: =COUNTIF(D9:D23,"Non-compliant") -> 2
B27: Not applicable | D27: =COUNTIF(D9:D23,"N/A") -> 1
B28: Not yet assessed | D28: =COUNTBLANK(D9:D23) -> 0
B29: Inspection compliance | D29: =IFERROR(D25/(D25+D26),"") -> 0.85714286
B30: Critical deficiencies | D30: =COUNTIF(F9:F23,"ESCALATE NOW") -> 1
B31: Outcome | D31: =IF(D28>0,"INCOMPLETE",IF(D30>0,"CRITICAL – escalate to Head of Institution",IF(D26>0,"Deficiencies – corrective action required","SATISFACTORY"))) -> CRITICAL – escalate to Head of Institution

Sheet Inspection Schedule
A1: Fire Safety Inspection Schedule & Log
A2: Drives KPI 17.1 Inspection Compliance and KPI 17.5 Critical Deficiency Rate
A4: Area / building | B4: Premises type | C4: Inspection type | D4: Planned date | E4: Date conducted | F4: Inspector | G4: Items assessed | H4: Items compliant | I4: Compliance % | J4: Critical deficiencies | K4: Status | L4: Remarks
A5: Academic Block A | B5: Academic block / classroom | C5: Scheduled fire safety inspection | D5: 46302 | E5: 46302 | F5: Fire and Safety Officer | G5: 14 | H5: 12 | I5: =IF(OR(G5="",H5="",G5=0),"",H5/G5) -> 0.85714286 | J5: 1 | K5: =IF(D5="","",IF(E5<>"","Completed",IF(D5<Dashboard!$C$5,"Missed",IF(D5-Dashboard!$C$5<=Lists!$R$5,"Due soon","Scheduled")))) -> Completed
A6: Chemistry Lab 2 | B6: Laboratory / research centre | C6: Laboratory | D6: 46287 | E6: 46288 | F6: Laboratory In-charge | G6: 11 | H6: 10 | I6: =IF(OR(G6="",H6="",G6=0),"",H6/G6) -> 0.90909091 | J6: 0 | K6: =IF(D6="","",IF(E6<>"","Completed",IF(D6<Dashboard!$C$5,"Missed",IF(D6-Dashboard!$C$5<=Lists!$R$5,"Due soon","Scheduled")))) -> Completed
A7: Central kitchen | B7: Kitchen / cafeteria | C7: Kitchen / cafeteria | D7: 46290 | E7: 46290 | F7: Canteen/Kitchen Supervisor | G7: 9 | H7: 9 | I7: =IF(OR(G7="",H7="",G7=0),"",H7/G7) -> 1 | J7: 0 | K7: =IF(D7="","",IF(E7<>"","Completed",IF(D7<Dashboard!$C$5,"Missed",IF(D7-Dashboard!$C$5<=Lists!$R$5,"Due soon","Scheduled")))) -> Completed
A8: Boys Hostel B | B8: Hostel / residential | C8: Hostel | D8: 46295 | F8: Hostel Warden | I8: =IF(OR(G8="",H8="",G8=0),"",H8/G8) | K8: =IF(D8="","",IF(E8<>"","Completed",IF(D8<Dashboard!$C$5,"Missed",IF(D8-Dashboard!$C$5<=Lists!$R$5,"Due soon","Scheduled")))) -> Missed
A9: Main electrical room | B9: Electrical room / server room / data centre | C9: Electrical installation | D9: 46313 | F9: Electrical Engineer/Authorized Technician | I9: =IF(OR(G9="",H9="",G9=0),"",H9/G9) | K9: =IF(D9="","",IF(E9<>"","Completed",IF(D9<Dashboard!$C$5,"Missed",IF(D9-Dashboard!$C$5<=Lists!$R$5,"Due soon","Scheduled")))) -> Due soon
A10: Library | B10: Library / auditorium / hall | C10: Fire protection systems | D10: 46331 | F10: Fire and Safety Officer | I10: =IF(OR(G10="",H10="",G10=0),"",H10/G10) | K10: =IF(D10="","",IF(E10<>"","Completed",IF(D10<Dashboard!$C$5,"Missed",IF(D10-Dashboard!$C$5<=Lists!$R$5,"Due soon","Scheduled")))) -> Scheduled
I11: =IF(OR(G11="",H11="",G11=0),"",H11/G11) | K11: =IF(D11="","",IF(E11<>"","Completed",IF(D11<Dashboard!$C$5,"Missed",IF(D11-Dashboard!$C$5<=Lists!$R$5,"Due soon","Scheduled"))))
I12: =IF(OR(G12="",H12="",G12=0),"",H12/G12) | K12: =IF(D12="","",IF(E12<>"","Completed",IF(D12<Dashboard!$C$5,"Missed",IF(D12-Dashboard!$C$5<=Lists!$R$5,"Due soon","Scheduled"))))
I13: =IF(OR(G13="",H13="",G13=0),"",H13/G13) | K13: =IF(D13="","",IF(E13<>"","Completed",IF(D13<Dashboard!$C$5,"Missed",IF(D13-Dashboard!$C$5<=Lists!$R$5,"Due soon","Scheduled"))))
I14: =IF(OR(G14="",H14="",G14=0),"",H14/G14) | K14: =IF(D14="","",IF(E14<>"","Completed",IF(D14<Dashboard!$C$5,"Missed",IF(D14-Dashboard!$C$5<=Lists!$R$5,"Due soon","Scheduled"))))
I15: =IF(OR(G15="",H15="",G15=0),"",H15/G15) | K15: =IF(D15="","",IF(E15<>"","Completed",IF(D15<Dashboard!$C$5,"Missed",IF(D15-Dashboard!$C$5<=Lists!$R$5,"Due soon","Scheduled"))))
I16: =IF(OR(G16="",H16="",G16=0),"",H16/G16) | K16: =IF(D16="","",IF(E16<>"","Completed",IF(D16<Dashboard!$C$5,"Missed",IF(D16-Dashboard!$C$5<=Lists!$R$5,"Due soon","Scheduled"))))
I17: =IF(OR(G17="",H17="",G17=0),"",H17/G17) | K17: =IF(D17="","",IF(E17<>"","Completed",IF(D17<Dashboard!$C$5,"Missed",IF(D17-Dashboard!$C$5<=Lists!$R$5,"Due soon","Scheduled"))))
I18: =IF(OR(G18="",H18="",G18=0),"",H18/G18) | K18: =IF(D18="","",IF(E18<>"","Completed",IF(D18<Dashboard!$C$5,"Missed",IF(D18-Dashboard!$C$5<=Lists!$R$5,"Due soon","Scheduled"))))
I19: =IF(OR(G19="",H19="",G19=0),"",H19/G19) | K19: =IF(D19="","",IF(E19<>"","Completed",IF(D19<Dashboard!$C$5,"Missed",IF(D19-Dashboard!$C$5<=Lists!$R$5,"Due soon","Scheduled"))))
I20: =IF(OR(G20="",H20="",G20=0),"",H20/G20) | K20: =IF(D20="","",IF(E20<>"","Completed",IF(D20<Dashboard!$C$5,"Missed",IF(D20-Dashboard!$C$5<=Lists!$R$5,"Due soon","Scheduled"))))
I21: =IF(OR(G21="",H21="",G21=0),"",H21/G21) | K21: =IF(D21="","",IF(E21<>"","Completed",IF(D21<Dashboard!$C$5,"Missed",IF(D21-Dashboard!$C$5<=Lists!$R$5,"Due soon","Scheduled"))))
I22: =IF(OR(G22="",H22="",G22=0),"",H22/G22) | K22: =IF(D22="","",IF(E22<>"","Completed",IF(D22<Dashboard!$C$5,"Missed",IF(D22-Dashboard!$C$5<=Lists!$R$5,"Due soon","Scheduled"))))
... I154: =IF(OR(G154="",H154="",G154=0),"",H154/G154) | K154: =IF(D154="","",IF(E154<>"","Completed",IF(D154<Dashboard!$C$5,"Missed",IF(D154-Dashboard!$C$5<=Lists!$R$5,"Due soon","Scheduled"))))

Sheet Hazard Reports & CAPA
A1: Fire Hazard Reports & Corrective Action Register
A2: SOP Section 15 – record → assess → protect → assign → deadline → verify → update register → escalate
A4: Ref | B4: Date reported | C4: Location | D4: Premises type | E4: Hazard category | F4: Description | G4: Reported by | H4: Severity | I4: Immediate protective measures | J4: Corrective action | K4: Owner | L4: Deadline | M4: Date closed | N4: Effectiveness verified? | O4: Risk register updated? | P4: Status | Q4: Escalate? | R4: Days open
A5: =IF(B5="","","HZ-"&TEXT(ROW()-4,"000")) -> HZ-001 | B5: 46277 | C5: Boys Hostel B, Room 214 | D5: Hostel / residential | E5: Battery/Charging | F5: E-scooter battery charging overnight in room | G5: Hostel Warden | H5: High | I5: Charger removed; resident briefed | J5: Provide designated charging area; update hostel rules | K5: Hostel Warden | L5: 46300 | P5: =IF(B5="","",IF(AND(M5<>"",N5="Yes"),"Closed",IF(M5<>"","Awaiting verification",IF(L5="","No deadline",IF(L5<Dashboard!$C$5,"Overdue",IF(L5-Dashboard!$C$5<=Lists!$R$5,"Due soon","Open")))))) -> Overdue | Q5: =IF(B5="","",IF(P5="Closed","—",IF(OR(H5="Critical",P5="Overdue"),"ESCALATE","—"))) -> ESCALATE | R5: =IF(B5="","",IF(M5<>"",M5,Dashboard!$C$5)-B5) -> 28
A6: =IF(B6="","","HZ-"&TEXT(ROW()-4,"000")) -> HZ-002 | B6: 46283 | C6: Central kitchen | D6: Kitchen / cafeteria | E6: Kitchen | F6: Gas hose cracked near burner 3 | G6: Canteen/Kitchen Supervisor | H6: Critical | I6: Gas supply isolated by technician | J6: Replace hose; inspect all connections | K6: Infrastructure/Maintenance Officer | L6: 46285 | M6: 46284 | N6: Yes | O6: Yes | P6: =IF(B6="","",IF(AND(M6<>"",N6="Yes"),"Closed",IF(M6<>"","Awaiting verification",IF(L6="","No deadline",IF(L6<Dashboard!$C$5,"Overdue",IF(L6-Dashboard!$C$5<=Lists!$R$5,"Due soon","Open")))))) -> Closed | Q6: =IF(B6="","",IF(P6="Closed","—",IF(OR(H6="Critical",P6="Overdue"),"ESCALATE","—"))) -> — | R6: =IF(B6="","",IF(M6<>"",M6,Dashboard!$C$5)-B6) -> 1
A7: =IF(B7="","","HZ-"&TEXT(ROW()-4,"000")) -> HZ-003 | B7: 46302 | C7: Academic Block A, stair 2 | D7: Academic block / classroom | E7: Fire Protection | F7: Fire door wedged open | G7: Fire and Safety Officer | H7: Critical | I7: Wedge removed; door closed | J7: Install hold-open device linked to alarm or enforce closure | K7: Infrastructure/Maintenance Officer | L7: 46316 | P7: =IF(B7="","",IF(AND(M7<>"",N7="Yes"),"Closed",IF(M7<>"","Awaiting verification",IF(L7="","No deadline",IF(L7<Dashboard!$C$5,"Overdue",IF(L7-Dashboard!$C$5<=Lists!$R$5,"Due soon","Open")))))) -> Due soon | Q7: =IF(B7="","",IF(P7="Closed","—",IF(OR(H7="Critical",P7="Overdue"),"ESCALATE","—"))) -> ESCALATE | R7: =IF(B7="","",IF(M7<>"",M7,Dashboard!$C$5)-B7) -> 3
A8: =IF(B8="","","HZ-"&TEXT(ROW()-4,"000")) -> HZ-004 | B8: 46302 | C8: Academic Block A, DB-3 | D8: Academic block / classroom | E8: Storage | F8: Cartons stored beside distribution board | G8: Fire and Safety Officer | H8: Medium | I8: Cartons moved | J8: Mark keep-clear zone; brief housekeeping | K8: Security Officer | L8: 46309 | M8: 46304 | P8: =IF(B8="","",IF(AND(M8<>"",N8="Yes"),"Closed",IF(M8<>"","Awaiting verification",IF(L8="","No deadline",IF(L8<Dashboard!$C$5,"Overdue",IF(L8-Dashboard!$C$5<=Lists!$R$5,"Due soon","Open")))))) -> Awaiting verification | Q8: =IF(B8="","",IF(P8="Closed","—",IF(OR(H8="Critical",P8="Overdue"),"ESCALATE","—"))) -> — | R8: =IF(B8="","",IF(M8<>"",M8,Dashboard!$C$5)-B8) -> 2
A9: =IF(B9="","","HZ-"&TEXT(ROW()-4,"000")) -> HZ-005 | B9: 46297 | C9: Mechanical workshop | D9: Workshop / store / maintenance | E9: Waste Management | F9: Oily rags in open bin | G9: Faculty/Staff | H9: Medium | I9: Rags removed | J9: Provide closed metal bin; daily disposal | K9: Department Head | L9: 46311 | P9: =IF(B9="","",IF(AND(M9<>"",N9="Yes"),"Closed",IF(M9<>"","Awaiting verification",IF(L9="","No deadline",IF(L9<Dashboard!$C$5,"Overdue",IF(L9-Dashboard!$C$5<=Lists!$R$5,"Due soon","Open")))))) -> Due soon | Q9: =IF(B9="","",IF(P9="Closed","—",IF(OR(H9="Critical",P9="Overdue"),"ESCALATE","—"))) -> — | R9: =IF(B9="","",IF(M9<>"",M9,Dashboard!$C$5)-B9) -> 8
A10: =IF(B10="","","HZ-"&TEXT(ROW()-4,"000")) | P10: =IF(B10="","",IF(AND(M10<>"",N10="Yes"),"Closed",IF(M10<>"","Awaiting verification",IF(L10="","No deadline",IF(L10<Dashboard!$C$5,"Overdue",IF(L10-Dashboard!$C$5<=Lists!$R$5,"Due soon","Open")))))) | Q10: =IF(B10="","",IF(P10="Closed","—",IF(OR(H10="Critical",P10="Overdue"),"ESCALATE","—"))) | R10: =IF(B10="","",IF(M10<>"",M10,Dashboard!$C$5)-B10)
A11: =IF(B11="","","HZ-"&TEXT(ROW()-4,"000")) | P11: =IF(B11="","",IF(AND(M11<>"",N11="Yes"),"Closed",IF(M11<>"","Awaiting verification",IF(L11="","No deadline",IF(L11<Dashboard!$C$5,"Overdue",IF(L11-Dashboard!$C$5<=Lists!$R$5,"Due soon","Open")))))) | Q11: =IF(B11="","",IF(P11="Closed","—",IF(OR(H11="Critical",P11="Overdue"),"ESCALATE","—"))) | R11: =IF(B11="","",IF(M11<>"",M11,Dashboard!$C$5)-B11)
A12: =IF(B12="","","HZ-"&TEXT(ROW()-4,"000")) | P12: =IF(B12="","",IF(AND(M12<>"",N12="Yes"),"Closed",IF(M12<>"","Awaiting verification",IF(L12="","No deadline",IF(L12<Dashboard!$C$5,"Overdue",IF(L12-Dashboard!$C$5<=Lists!$R$5,"Due soon","Open")))))) | Q12: =IF(B12="","",IF(P12="Closed","—",IF(OR(H12="Critical",P12="Overdue"),"ESCALATE","—"))) | R12: =IF(B12="","",IF(M12<>"",M12,Dashboard!$C$5)-B12)
A13: =IF(B13="","","HZ-"&TEXT(ROW()-4,"000")) | P13: =IF(B13="","",IF(AND(M13<>"",N13="Yes"),"Closed",IF(M13<>"","Awaiting verification",IF(L13="","No deadline",IF(L13<Dashboard!$C$5,"Overdue",IF(L13-Dashboard!$C$5<=Lists!$R$5,"Due soon","Open")))))) | Q13: =IF(B13="","",IF(P13="Closed","—",IF(OR(H13="Critical",P13="Overdue"),"ESCALATE","—"))) | R13: =IF(B13="","",IF(M13<>"",M13,Dashboard!$C$5)-B13)
A14: =IF(B14="","","HZ-"&TEXT(ROW()-4,"000")) | P14: =IF(B14="","",IF(AND(M14<>"",N14="Yes"),"Closed",IF(M14<>"","Awaiting verification",IF(L14="","No deadline",IF(L14<Dashboard!$C$5,"Overdue",IF(L14-Dashboard!$C$5<=Lists!$R$5,"Due soon","Open")))))) | Q14: =IF(B14="","",IF(P14="Closed","—",IF(OR(H14="Critical",P14="Overdue"),"ESCALATE","—"))) | R14: =IF(B14="","",IF(M14<>"",M14,Dashboard!$C$5)-B14)
A15: =IF(B15="","","HZ-"&TEXT(ROW()-4,"000")) | P15: =IF(B15="","",IF(AND(M15<>"",N15="Yes"),"Closed",IF(M15<>"","Awaiting verification",IF(L15="","No deadline",IF(L15<Dashboard!$C$5,"Overdue",IF(L15-Dashboard!$C$5<=Lists!$R$5,"Due soon","Open")))))) | Q15: =IF(B15="","",IF(P15="Closed","—",IF(OR(H15="Critical",P15="Overdue"),"ESCALATE","—"))) | R15: =IF(B15="","",IF(M15<>"",M15,Dashboard!$C$5)-B15)
A16: =IF(B16="","","HZ-"&TEXT(ROW()-4,"000")) | P16: =IF(B16="","",IF(AND(M16<>"",N16="Yes"),"Closed",IF(M16<>"","Awaiting verification",IF(L16="","No deadline",IF(L16<Dashboard!$C$5,"Overdue",IF(L16-Dashboard!$C$5<=Lists!$R$5,"Due soon","Open")))))) | Q16: =IF(B16="","",IF(P16="Closed","—",IF(OR(H16="Critical",P16="Overdue"),"ESCALATE","—"))) | R16: =IF(B16="","",IF(M16<>"",M16,Dashboard!$C$5)-B16)
A17: =IF(B17="","","HZ-"&TEXT(ROW()-4,"000")) | P17: =IF(B17="","",IF(AND(M17<>"",N17="Yes"),"Closed",IF(M17<>"","Awaiting verification",IF(L17="","No deadline",IF(L17<Dashboard!$C$5,"Overdue",IF(L17-Dashboard!$C$5<=Lists!$R$5,"Due soon","Open")))))) | Q17: =IF(B17="","",IF(P17="Closed","—",IF(OR(H17="Critical",P17="Overdue"),"ESCALATE","—"))) | R17: =IF(B17="","",IF(M17<>"",M17,Dashboard!$C$5)-B17)
A18: =IF(B18="","","HZ-"&TEXT(ROW()-4,"000")) | P18: =IF(B18="","",IF(AND(M18<>"",N18="Yes"),"Closed",IF(M18<>"","Awaiting verification",IF(L18="","No deadline",IF(L18<Dashboard!$C$5,"Overdue",IF(L18-Dashboard!$C$5<=Lists!$R$5,"Due soon","Open")))))) | Q18: =IF(B18="","",IF(P18="Closed","—",IF(OR(H18="Critical",P18="Overdue"),"ESCALATE","—"))) | R18: =IF(B18="","",IF(M18<>"",M18,Dashboard!$C$5)-B18)
A19: =IF(B19="","","HZ-"&TEXT(ROW()-4,"000")) | P19: =IF(B19="","",IF(AND(M19<>"",N19="Yes"),"Closed",IF(M19<>"","Awaiting verification",IF(L19="","No deadline",IF(L19<Dashboard!$C$5,"Overdue",IF(L19-Dashboard!$C$5<=Lists!$R$5,"Due soon","Open")))))) | Q19: =IF(B19="","",IF(P19="Closed","—",IF(OR(H19="Critical",P19="Overdue"),"ESCALATE","—"))) | R19: =IF(B19="","",IF(M19<>"",M19,Dashboard!$C$5)-B19)
A20: =IF(B20="","","HZ-"&TEXT(ROW()-4,"000")) | P20: =IF(B20="","",IF(AND(M20<>"",N20="Yes"),"Closed",IF(M20<>"","Awaiting verification",IF(L20="","No deadline",IF(L20<Dashboard!$C$5,"Overdue",IF(L20-Dashboard!$C$5<=Lists!$R$5,"Due soon","Open")))))) | Q20: =IF(B20="","",IF(P20="Closed","—",IF(OR(H20="Critical",P20="Overdue"),"ESCALATE","—"))) | R20: =IF(B20="","",IF(M20<>"",M20,Dashboard!$C$5)-B20)
A21: =IF(B21="","","HZ-"&TEXT(ROW()-4,"000")) | P21: =IF(B21="","",IF(AND(M21<>"",N21="Yes"),"Closed",IF(M21<>"","Awaiting verification",IF(L21="","No deadline",IF(L21<Dashboard!$C$5,"Overdue",IF(L21-Dashboard!$C$5<=Lists!$R$5,"Due soon","Open")))))) | Q21: =IF(B21="","",IF(P21="Closed","—",IF(OR(H21="Critical",P21="Overdue"),"ESCALATE","—"))) | R21: =IF(B21="","",IF(M21<>"",M21,Dashboard!$C$5)-B21)
... A64: =IF(B64="","","HZ-"&TEXT(ROW()-4,"000")) | P64: =IF(B64="","",IF(AND(M64<>"",N64="Yes"),"Closed",IF(M64<>"","Awaiting verification",IF(L64="","No deadline",IF(L64<Dashboard!$C$5,"Overdue",IF(L64-Dashboard!$C$5<=Lists!$R$5,"Due soon","Open")))))) | Q64: =IF(B64="","",IF(P64="Closed","—",IF(OR(H64="Critical",P64="Overdue"),"ESCALATE","—"))) | R64: =IF(B64="","",IF(M64<>"",M64,Dashboard!$C$5)-B64)

Sheet Fire Protection Register
A1: Fire Protection Equipment & System Register
A2: SOP Section 12 – inspection, testing and servicing; interim controls when a critical system is impaired
A4: Asset ID | B4: Equipment / system | C4: Location | D4: Last inspected / serviced | E4: Service interval (days) | F4: Next due | G4: Functional? | H4: Critical system? | I4: Interim control in place (if impaired)? | J4: Status | K4: Serviced by | L4: Remarks
A5: FA-01 | B5: Automatic fire detection system | C5: Academic Block A | D5: 46218 | E5: 180 | F5: =IF(OR(D5="",E5=""),"",D5+E5) -> 46398 | G5: Yes | H5: Yes | J5: =IF(B5="","",IF(G5="No",IF(I5="Yes","Impaired – interim control",IF(H5="Yes","IMPAIRED – NO INTERIM CONTROL","Impaired – repair")),IF(F5="","Not scheduled",IF(F5<Dashboard!$C$5,"Service overdue",IF(F5-Dashboard!$C$5<=Lists!$R$5,"Due soon","In service"))))) -> In service
A6: MCP-A | B6: Manual call point | C6: Academic Block A – all floors | D6: 46218 | E6: 180 | F6: =IF(OR(D6="",E6=""),"",D6+E6) -> 46398 | G6: Yes | H6: Yes | J6: =IF(B6="","",IF(G6="No",IF(I6="Yes","Impaired – interim control",IF(H6="Yes","IMPAIRED – NO INTERIM CONTROL","Impaired – repair")),IF(F6="","Not scheduled",IF(F6<Dashboard!$C$5,"Service overdue",IF(F6-Dashboard!$C$5<=Lists!$R$5,"Due soon","In service"))))) -> In service
A7: EL-A | B7: Emergency lighting | C7: Academic Block A | D7: 46266 | E7: 30 | F7: =IF(OR(D7="",E7=""),"",D7+E7) -> 46296 | G7: Yes | H7: Yes | J7: =IF(B7="","",IF(G7="No",IF(I7="Yes","Impaired – interim control",IF(H7="Yes","IMPAIRED – NO INTERIM CONTROL","Impaired – repair")),IF(F7="","Not scheduled",IF(F7<Dashboard!$C$5,"Service overdue",IF(F7-Dashboard!$C$5<=Lists!$R$5,"Due soon","In service"))))) -> Service overdue
A8: FE-014 | B8: Fire extinguisher | C8: Chemistry Lab 2 | D8: 46114 | E8: 180 | F8: =IF(OR(D8="",E8=""),"",D8+E8) -> 46294 | G8: Yes | H8: No | J8: =IF(B8="","",IF(G8="No",IF(I8="Yes","Impaired – interim control",IF(H8="Yes","IMPAIRED – NO INTERIM CONTROL","Impaired – repair")),IF(F8="","Not scheduled",IF(F8<Dashboard!$C$5,"Service overdue",IF(F8-Dashboard!$C$5<=Lists!$R$5,"Due soon","In service"))))) -> Service overdue | L8: 6-monthly service missed
A9: FE-022 | B9: Fire extinguisher | C9: Central kitchen | D9: 46275 | E9: 90 | F9: =IF(OR(D9="",E9=""),"",D9+E9) -> 46365 | G9: Yes | H9: No | J9: =IF(B9="","",IF(G9="No",IF(I9="Yes","Impaired – interim control",IF(H9="Yes","IMPAIRED – NO INTERIM CONTROL","Impaired – repair")),IF(F9="","Not scheduled",IF(F9<Dashboard!$C$5,"Service overdue",IF(F9-Dashboard!$C$5<=Lists!$R$5,"Due soon","In service"))))) -> In service
A10: HY-02 | B10: Hydrant / hose system | C10: Hostel B ground floor | D10: 46254 | E10: 90 | F10: =IF(OR(D10="",E10=""),"",D10+E10) -> 46344 | G10: No | H10: Yes | I10: Yes | J10: =IF(B10="","",IF(G10="No",IF(I10="Yes","Impaired – interim control",IF(H10="Yes","IMPAIRED – NO INTERIM CONTROL","Impaired – repair")),IF(F10="","Not scheduled",IF(F10<Dashboard!$C$5,"Service overdue",IF(F10-Dashboard!$C$5<=Lists!$R$5,"Due soon","In service"))))) -> Impaired – interim control | L10: Pump pressure low; fire watch and extra extinguishers placed pending repair
A11: SPR-L | B11: Sprinkler / fixed suppression | C11: Library stack area | D11: 46203 | E11: 180 | F11: =IF(OR(D11="",E11=""),"",D11+E11) -> 46383 | G11: Yes | H11: Yes | J11: =IF(B11="","",IF(G11="No",IF(I11="Yes","Impaired – interim control",IF(H11="Yes","IMPAIRED – NO INTERIM CONTROL","Impaired – repair")),IF(F11="","Not scheduled",IF(F11<Dashboard!$C$5,"Service overdue",IF(F11-Dashboard!$C$5<=Lists!$R$5,"Due soon","In service"))))) -> In service
A12: FD-S2 | B12: Fire door / compartmentation | C12: Academic Block A stair 2 | D12: 46302 | E12: 90 | F12: =IF(OR(D12="",E12=""),"",D12+E12) -> 46392 | G12: Yes | H12: Yes | J12: =IF(B12="","",IF(G12="No",IF(I12="Yes","Impaired – interim control",IF(H12="Yes","IMPAIRED – NO INTERIM CONTROL","Impaired – repair")),IF(F12="","Not scheduled",IF(F12<Dashboard!$C$5,"Service overdue",IF(F12-Dashboard!$C$5<=Lists!$R$5,"Due soon","In service"))))) -> In service
F13: =IF(OR(D13="",E13=""),"",D13+E13) | J13: =IF(B13="","",IF(G13="No",IF(I13="Yes","Impaired – interim control",IF(H13="Yes","IMPAIRED – NO INTERIM CONTROL","Impaired – repair")),IF(F13="","Not scheduled",IF(F13<Dashboard!$C$5,"Service overdue",IF(F13-Dashboard!$C$5<=Lists!$R$5,"Due soon","In service")))))
F14: =IF(OR(D14="",E14=""),"",D14+E14) | J14: =IF(B14="","",IF(G14="No",IF(I14="Yes","Impaired – interim control",IF(H14="Yes","IMPAIRED – NO INTERIM CONTROL","Impaired – repair")),IF(F14="","Not scheduled",IF(F14<Dashboard!$C$5,"Service overdue",IF(F14-Dashboard!$C$5<=Lists!$R$5,"Due soon","In service")))))
F15: =IF(OR(D15="",E15=""),"",D15+E15) | J15: =IF(B15="","",IF(G15="No",IF(I15="Yes","Impaired – interim control",IF(H15="Yes","IMPAIRED – NO INTERIM CONTROL","Impaired – repair")),IF(F15="","Not scheduled",IF(F15<Dashboard!$C$5,"Service overdue",IF(F15-Dashboard!$C$5<=Lists!$R$5,"Due soon","In service")))))
F16: =IF(OR(D16="",E16=""),"",D16+E16) | J16: =IF(B16="","",IF(G16="No",IF(I16="Yes","Impaired – interim control",IF(H16="Yes","IMPAIRED – NO INTERIM CONTROL","Impaired – repair")),IF(F16="","Not scheduled",IF(F16<Dashboard!$C$5,"Service overdue",IF(F16-Dashboard!$C$5<=Lists!$R$5,"Due soon","In service")))))
F17: =IF(OR(D17="",E17=""),"",D17+E17) | J17: =IF(B17="","",IF(G17="No",IF(I17="Yes","Impaired – interim control",IF(H17="Yes","IMPAIRED – NO INTERIM CONTROL","Impaired – repair")),IF(F17="","Not scheduled",IF(F17<Dashboard!$C$5,"Service overdue",IF(F17-Dashboard!$C$5<=Lists!$R$5,"Due soon","In service")))))
F18: =IF(OR(D18="",E18=""),"",D18+E18) | J18: =IF(B18="","",IF(G18="No",IF(I18="Yes","Impaired – interim control",IF(H18="Yes","IMPAIRED – NO INTERIM CONTROL","Impaired – repair")),IF(F18="","Not scheduled",IF(F18<Dashboard!$C$5,"Service overdue",IF(F18-Dashboard!$C$5<=Lists!$R$5,"Due soon","In service")))))
F19: =IF(OR(D19="",E19=""),"",D19+E19) | J19: =IF(B19="","",IF(G19="No",IF(I19="Yes","Impaired – interim control",IF(H19="Yes","IMPAIRED – NO INTERIM CONTROL","Impaired – repair")),IF(F19="","Not scheduled",IF(F19<Dashboard!$C$5,"Service overdue",IF(F19-Dashboard!$C$5<=Lists!$R$5,"Due soon","In service")))))
F20: =IF(OR(D20="",E20=""),"",D20+E20) | J20: =IF(B20="","",IF(G20="No",IF(I20="Yes","Impaired – interim control",IF(H20="Yes","IMPAIRED – NO INTERIM CONTROL","Impaired – repair")),IF(F20="","Not scheduled",IF(F20<Dashboard!$C$5,"Service overdue",IF(F20-Dashboard!$C$5<=Lists!$R$5,"Due soon","In service")))))
F21: =IF(OR(D21="",E21=""),"",D21+E21) | J21: =IF(B21="","",IF(G21="No",IF(I21="Yes","Impaired – interim control",IF(H21="Yes","IMPAIRED – NO INTERIM CONTROL","Impaired – repair")),IF(F21="","Not scheduled",IF(F21<Dashboard!$C$5,"Service overdue",IF(F21-Dashboard!$C$5<=Lists!$R$5,"Due soon","In service")))))
F22: =IF(OR(D22="",E22=""),"",D22+E22) | J22: =IF(B22="","",IF(G22="No",IF(I22="Yes","Impaired – interim control",IF(H22="Yes","IMPAIRED – NO INTERIM CONTROL","Impaired – repair")),IF(F22="","Not scheduled",IF(F22<Dashboard!$C$5,"Service overdue",IF(F22-Dashboard!$C$5<=Lists!$R$5,"Due soon","In service")))))
F23: =IF(OR(D23="",E23=""),"",D23+E23) | J23: =IF(B23="","",IF(G23="No",IF(I23="Yes","Impaired – interim control",IF(H23="Yes","IMPAIRED – NO INTERIM CONTROL","Impaired – repair")),IF(F23="","Not scheduled",IF(F23<Dashboard!$C$5,"Service overdue",IF(F23-Dashboard!$C$5<=Lists!$R$5,"Due soon","In service")))))
F24: =IF(OR(D24="",E24=""),"",D24+E24) | J24: =IF(B24="","",IF(G24="No",IF(I24="Yes","Impaired – interim control",IF(H24="Yes","IMPAIRED – NO INTERIM CONTROL","Impaired – repair")),IF(F24="","Not scheduled",IF(F24<Dashboard!$C$5,"Service overdue",IF(F24-Dashboard!$C$5<=Lists!$R$5,"Due soon","In service")))))
... F154: =IF(OR(D154="",E154=""),"",D154+E154) | J154: =IF(B154="","",IF(G154="No",IF(I154="Yes","Impaired – interim control",IF(H154="Yes","IMPAIRED – NO INTERIM CONTROL","Impaired – repair")),IF(F154="","Not scheduled",IF(F154<Dashboard!$C$5,"Service overdue",IF(F154-Dashboard!$C$5<=Lists!$R$5,"Due soon","In service")))))

Sheet Hot-Work Permits
A1: Hot-Work Permit Register
A2: SOP Section 11 – hot work shall not be permitted where essential safety conditions cannot be achieved
A4: Permit no. | B4: Date | C4: Location | D4: Work type | E4: Contractor / person | F4: Authorization before work | G4: Work area inspected | H4: Combustibles removed / protected | I4: Concealed & adjacent areas assessed | J4: Fire-protection equipment provided | K4: Competent fire watch assigned | L4: Contractor competency verified | M4: Cylinder & equipment safety | N4: Post-work inspection done | O4: Permit documented & closed | P4: Pre-work check | Q4: Permit status
A5: HW-031 | B5: 46291 | C5: Mechanical workshop | D5: Welding | E5: M/s Steelcraft | F5: Yes | G5: Yes | H5: Yes | I5: Yes | J5: Yes | K5: Yes | L5: Yes | M5: Yes | N5: Yes | O5: Yes | P5: =IF(C5="","",IF(COUNTIF(F5:M5,"No")>0,"Conditions NOT met",IF(COUNTBLANK(F5:M5)>0,"Incomplete","All conditions met"))) -> All conditions met | Q5: =IF(C5="","",IF(P5="Conditions NOT met","STOP – do not permit",IF(P5="Incomplete","Not authorized – complete checks",IF(AND(N5="Yes",O5="Yes"),"Closed","Authorized – open")))) -> Closed
A6: HW-032 | B6: 46303 | C6: Hostel B roof | D6: Cutting | E6: M/s Roofline | F6: Yes | G6: Yes | H6: Yes | I6: Yes | J6: Yes | K6: Yes | L6: Yes | M6: Yes | P6: =IF(C6="","",IF(COUNTIF(F6:M6,"No")>0,"Conditions NOT met",IF(COUNTBLANK(F6:M6)>0,"Incomplete","All conditions met"))) -> All conditions met | Q6: =IF(C6="","",IF(P6="Conditions NOT met","STOP – do not permit",IF(P6="Incomplete","Not authorized – complete checks",IF(AND(N6="Yes",O6="Yes"),"Closed","Authorized – open")))) -> Authorized – open
A7: HW-033 | B7: 46304 | C7: Library annex (renovation) | D7: Grinding | E7: M/s BuildRight | F7: Yes | G7: Yes | H7: No | I7: Yes | J7: Yes | K7: N/A | L7: Yes | M7: N/A | P7: =IF(C7="","",IF(COUNTIF(F7:M7,"No")>0,"Conditions NOT met",IF(COUNTBLANK(F7:M7)>0,"Incomplete","All conditions met"))) -> Conditions NOT met | Q7: =IF(C7="","",IF(P7="Conditions NOT met","STOP – do not permit",IF(P7="Incomplete","Not authorized – complete checks",IF(AND(N7="Yes",O7="Yes"),"Closed","Authorized – open")))) -> STOP – do not permit
P8: =IF(C8="","",IF(COUNTIF(F8:M8,"No")>0,"Conditions NOT met",IF(COUNTBLANK(F8:M8)>0,"Incomplete","All conditions met"))) | Q8: =IF(C8="","",IF(P8="Conditions NOT met","STOP – do not permit",IF(P8="Incomplete","Not authorized – complete checks",IF(AND(N8="Yes",O8="Yes"),"Closed","Authorized – open"))))
P9: =IF(C9="","",IF(COUNTIF(F9:M9,"No")>0,"Conditions NOT met",IF(COUNTBLANK(F9:M9)>0,"Incomplete","All conditions met"))) | Q9: =IF(C9="","",IF(P9="Conditions NOT met","STOP – do not permit",IF(P9="Incomplete","Not authorized – complete checks",IF(AND(N9="Yes",O9="Yes"),"Closed","Authorized – open"))))
P10: =IF(C10="","",IF(COUNTIF(F10:M10,"No")>0,"Conditions NOT met",IF(COUNTBLANK(F10:M10)>0,"Incomplete","All conditions met"))) | Q10: =IF(C10="","",IF(P10="Conditions NOT met","STOP – do not permit",IF(P10="Incomplete","Not authorized – complete checks",IF(AND(N10="Yes",O10="Yes"),"Closed","Authorized – open"))))
P11: =IF(C11="","",IF(COUNTIF(F11:M11,"No")>0,"Conditions NOT met",IF(COUNTBLANK(F11:M11)>0,"Incomplete","All conditions met"))) | Q11: =IF(C11="","",IF(P11="Conditions NOT met","STOP – do not permit",IF(P11="Incomplete","Not authorized – complete checks",IF(AND(N11="Yes",O11="Yes"),"Closed","Authorized – open"))))
P12: =IF(C12="","",IF(COUNTIF(F12:M12,"No")>0,"Conditions NOT met",IF(COUNTBLANK(F12:M12)>0,"Incomplete","All conditions met"))) | Q12: =IF(C12="","",IF(P12="Conditions NOT met","STOP – do not permit",IF(P12="Incomplete","Not authorized – complete checks",IF(AND(N12="Yes",O12="Yes"),"Closed","Authorized – open"))))
P13: =IF(C13="","",IF(COUNTIF(F13:M13,"No")>0,"Conditions NOT met",IF(COUNTBLANK(F13:M13)>0,"Incomplete","All conditions met"))) | Q13: =IF(C13="","",IF(P13="Conditions NOT met","STOP – do not permit",IF(P13="Incomplete","Not authorized – complete checks",IF(AND(N13="Yes",O13="Yes"),"Closed","Authorized – open"))))
P14: =IF(C14="","",IF(COUNTIF(F14:M14,"No")>0,"Conditions NOT met",IF(COUNTBLANK(F14:M14)>0,"Incomplete","All conditions met"))) | Q14: =IF(C14="","",IF(P14="Conditions NOT met","STOP – do not permit",IF(P14="Incomplete","Not authorized – complete checks",IF(AND(N14="Yes",O14="Yes"),"Closed","Authorized – open"))))
P15: =IF(C15="","",IF(COUNTIF(F15:M15,"No")>0,"Conditions NOT met",IF(COUNTBLANK(F15:M15)>0,"Incomplete","All conditions met"))) | Q15: =IF(C15="","",IF(P15="Conditions NOT met","STOP – do not permit",IF(P15="Incomplete","Not authorized – complete checks",IF(AND(N15="Yes",O15="Yes"),"Closed","Authorized – open"))))
P16: =IF(C16="","",IF(COUNTIF(F16:M16,"No")>0,"Conditions NOT met",IF(COUNTBLANK(F16:M16)>0,"Incomplete","All conditions met"))) | Q16: =IF(C16="","",IF(P16="Conditions NOT met","STOP – do not permit",IF(P16="Incomplete","Not authorized – complete checks",IF(AND(N16="Yes",O16="Yes"),"Closed","Authorized – open"))))
P17: =IF(C17="","",IF(COUNTIF(F17:M17,"No")>0,"Conditions NOT met",IF(COUNTBLANK(F17:M17)>0,"Incomplete","All conditions met"))) | Q17: =IF(C17="","",IF(P17="Conditions NOT met","STOP – do not permit",IF(P17="Incomplete","Not authorized – complete checks",IF(AND(N17="Yes",O17="Yes"),"Closed","Authorized – open"))))
P18: =IF(C18="","",IF(COUNTIF(F18:M18,"No")>0,"Conditions NOT met",IF(COUNTBLANK(F18:M18)>0,"Incomplete","All conditions met"))) | Q18: =IF(C18="","",IF(P18="Conditions NOT met","STOP – do not permit",IF(P18="Incomplete","Not authorized – complete checks",IF(AND(N18="Yes",O18="Yes"),"Closed","Authorized – open"))))
P19: =IF(C19="","",IF(COUNTIF(F19:M19,"No")>0,"Conditions NOT met",IF(COUNTBLANK(F19:M19)>0,"Incomplete","All conditions met"))) | Q19: =IF(C19="","",IF(P19="Conditions NOT met","STOP – do not permit",IF(P19="Incomplete","Not authorized – complete checks",IF(AND(N19="Yes",O19="Yes"),"Closed","Authorized – open"))))
... P64: =IF(C64="","",IF(COUNTIF(F64:M64,"No")>0,"Conditions NOT met",IF(COUNTBLANK(F64:M64)>0,"Incomplete","All conditions met"))) | Q64: =IF(C64="","",IF(P64="Conditions NOT met","STOP – do not permit",IF(P64="Incomplete","Not authorized – complete checks",IF(AND(N64="Yes",O64="Yes"),"Closed","Authorized – open"))))

Sheet Flammable Inventory
A1: Flammable & Combustible Material Inventory
A2: SOP Sections 7 & 8 – controlled quantities, approved storage, segregation, labelling, secured cylinders
A4: Item ID | B4: Material | C4: Class | D4: Location / store | E4: Quantity held | F4: Max permitted | G4: Unit | H4: Approved storage? | I4: Segregated from ignition / incompatibles? | J4: Labelled & closed? | K4: Cylinder secured? (gas only) | L4: Quantity check | M4: Compliance | N4: Remarks
A5: FL-01 | B5: Acetone | C5: Flammable liquid | D5: Chem Lab 2 – flammables cabinet | E5: 8 | F5: 10 | G5: L | H5: Yes | I5: Yes | J5: Yes | K5: N/A | L5: =IF(OR(E5="",F5=""),"",IF(E5>F5,"Over limit","Within limit")) -> Within limit | M5: =IF(B5="","",IF(AND(H5="Yes",I5="Yes",J5="Yes",K5<>"No",L5<>"Over limit"),"Compliant",IF(OR(H5="",I5="",J5=""),"Incomplete","Action needed"))) -> Compliant
A6: FL-02 | B6: Ethanol | C6: Flammable liquid | D6: Chem Lab 2 – bench | E6: 4 | F6: 2 | G6: L | H6: No | I6: Yes | J6: Yes | K6: N/A | L6: =IF(OR(E6="",F6=""),"",IF(E6>F6,"Over limit","Within limit")) -> Over limit | M6: =IF(B6="","",IF(AND(H6="Yes",I6="Yes",J6="Yes",K6<>"No",L6<>"Over limit"),"Compliant",IF(OR(H6="",I6="",J6=""),"Incomplete","Action needed"))) -> Action needed | N6: Bench quantity exceeds limit; return excess to cabinet
A7: FL-03 | B7: LPG cylinders | C7: Flammable gas cylinder | D7: Central kitchen – cylinder bank | E7: 6 | F7: 8 | G7: nos | H7: Yes | I7: Yes | J7: Yes | K7: Yes | L7: =IF(OR(E7="",F7=""),"",IF(E7>F7,"Over limit","Within limit")) -> Within limit | M7: =IF(B7="","",IF(AND(H7="Yes",I7="Yes",J7="Yes",K7<>"No",L7<>"Over limit"),"Compliant",IF(OR(H7="",I7="",J7=""),"Incomplete","Action needed"))) -> Compliant
A8: FL-04 | B8: Acetylene cylinder | C8: Flammable gas cylinder | D8: Mechanical workshop | E8: 2 | F8: 2 | G8: nos | H8: Yes | I8: Yes | J8: Yes | K8: No | L8: =IF(OR(E8="",F8=""),"",IF(E8>F8,"Over limit","Within limit")) -> Within limit | M8: =IF(B8="","",IF(AND(H8="Yes",I8="Yes",J8="Yes",K8<>"No",L8<>"Over limit"),"Compliant",IF(OR(H8="",I8="",J8=""),"Incomplete","Action needed"))) -> Action needed | N8: Chain missing on cylinder trolley
A9: FL-05 | B9: Paint thinner | C9: Flammable liquid | D9: Maintenance store | E9: 15 | F9: 20 | G9: L | H9: Yes | I9: Yes | J9: Yes | K9: N/A | L9: =IF(OR(E9="",F9=""),"",IF(E9>F9,"Over limit","Within limit")) -> Within limit | M9: =IF(B9="","",IF(AND(H9="Yes",I9="Yes",J9="Yes",K9<>"No",L9<>"Over limit"),"Compliant",IF(OR(H9="",I9="",J9=""),"Incomplete","Action needed"))) -> Compliant
L10: =IF(OR(E10="",F10=""),"",IF(E10>F10,"Over limit","Within limit")) | M10: =IF(B10="","",IF(AND(H10="Yes",I10="Yes",J10="Yes",K10<>"No",L10<>"Over limit"),"Compliant",IF(OR(H10="",I10="",J10=""),"Incomplete","Action needed")))
L11: =IF(OR(E11="",F11=""),"",IF(E11>F11,"Over limit","Within limit")) | M11: =IF(B11="","",IF(AND(H11="Yes",I11="Yes",J11="Yes",K11<>"No",L11<>"Over limit"),"Compliant",IF(OR(H11="",I11="",J11=""),"Incomplete","Action needed")))
L12: =IF(OR(E12="",F12=""),"",IF(E12>F12,"Over limit","Within limit")) | M12: =IF(B12="","",IF(AND(H12="Yes",I12="Yes",J12="Yes",K12<>"No",L12<>"Over limit"),"Compliant",IF(OR(H12="",I12="",J12=""),"Incomplete","Action needed")))
L13: =IF(OR(E13="",F13=""),"",IF(E13>F13,"Over limit","Within limit")) | M13: =IF(B13="","",IF(AND(H13="Yes",I13="Yes",J13="Yes",K13<>"No",L13<>"Over limit"),"Compliant",IF(OR(H13="",I13="",J13=""),"Incomplete","Action needed")))
L14: =IF(OR(E14="",F14=""),"",IF(E14>F14,"Over limit","Within limit")) | M14: =IF(B14="","",IF(AND(H14="Yes",I14="Yes",J14="Yes",K14<>"No",L14<>"Over limit"),"Compliant",IF(OR(H14="",I14="",J14=""),"Incomplete","Action needed")))
L15: =IF(OR(E15="",F15=""),"",IF(E15>F15,"Over limit","Within limit")) | M15: =IF(B15="","",IF(AND(H15="Yes",I15="Yes",J15="Yes",K15<>"No",L15<>"Over limit"),"Compliant",IF(OR(H15="",I15="",J15=""),"Incomplete","Action needed")))
L16: =IF(OR(E16="",F16=""),"",IF(E16>F16,"Over limit","Within limit")) | M16: =IF(B16="","",IF(AND(H16="Yes",I16="Yes",J16="Yes",K16<>"No",L16<>"Over limit"),"Compliant",IF(OR(H16="",I16="",J16=""),"Incomplete","Action needed")))
L17: =IF(OR(E17="",F17=""),"",IF(E17>F17,"Over limit","Within limit")) | M17: =IF(B17="","",IF(AND(H17="Yes",I17="Yes",J17="Yes",K17<>"No",L17<>"Over limit"),"Compliant",IF(OR(H17="",I17="",J17=""),"Incomplete","Action needed")))
L18: =IF(OR(E18="",F18=""),"",IF(E18>F18,"Over limit","Within limit")) | M18: =IF(B18="","",IF(AND(H18="Yes",I18="Yes",J18="Yes",K18<>"No",L18<>"Over limit"),"Compliant",IF(OR(H18="",I18="",J18=""),"Incomplete","Action needed")))
L19: =IF(OR(E19="",F19=""),"",IF(E19>F19,"Over limit","Within limit")) | M19: =IF(B19="","",IF(AND(H19="Yes",I19="Yes",J19="Yes",K19<>"No",L19<>"Over limit"),"Compliant",IF(OR(H19="",I19="",J19=""),"Incomplete","Action needed")))
L20: =IF(OR(E20="",F20=""),"",IF(E20>F20,"Over limit","Within limit")) | M20: =IF(B20="","",IF(AND(H20="Yes",I20="Yes",J20="Yes",K20<>"No",L20<>"Over limit"),"Compliant",IF(OR(H20="",I20="",J20=""),"Incomplete","Action needed")))
L21: =IF(OR(E21="",F21=""),"",IF(E21>F21,"Over limit","Within limit")) | M21: =IF(B21="","",IF(AND(H21="Yes",I21="Yes",J21="Yes",K21<>"No",L21<>"Over limit"),"Compliant",IF(OR(H21="",I21="",J21=""),"Incomplete","Action needed")))
... L104: =IF(OR(E104="",F104=""),"",IF(E104>F104,"Over limit","Within limit")) | M104: =IF(B104="","",IF(AND(H104="Yes",I104="Yes",J104="Yes",K104<>"No",L104<>"Over limit"),"Compliant",IF(OR(H104="",I104="",J104=""),"Incomplete","Action needed")))

Sheet Hostel & Kitchen Checks
